[2024-08-24T12:26:16.059+0000] {local_task_job_runner.py:123} INFO - ::group::Pre task execution logs
[2024-08-24T12:26:16.091+0000] {taskinstance.py:2603} INFO - Dependencies all met for dep_context=non-requeueable deps ti=<TaskInstance: bybit_tick_fetcher.fetch_data_task manual__2024-08-24T12:21:13.878822+00:00 [queued]>
[2024-08-24T12:26:16.099+0000] {taskinstance.py:2603} INFO - Dependencies all met for dep_context=requeueable deps ti=<TaskInstance: bybit_tick_fetcher.fetch_data_task manual__2024-08-24T12:21:13.878822+00:00 [queued]>
[2024-08-24T12:26:16.100+0000] {taskinstance.py:2856} INFO - Starting attempt 2 of 2
[2024-08-24T12:26:16.113+0000] {taskinstance.py:2879} INFO - Executing <Task(PythonOperator): fetch_data_task> on 2024-08-24 12:21:13.878822+00:00
[2024-08-24T12:26:16.124+0000] {logging_mixin.py:190} WARNING - /home/***/.local/lib/python3.12/site-packages/***/task/task_runner/standard_task_runner.py:70 DeprecationWarning: This process (pid=3398) is multi-threaded, use of fork() may lead to deadlocks in the child.
[2024-08-24T12:26:16.123+0000] {standard_task_runner.py:104} INFO - Running: ['***', 'tasks', 'run', 'bybit_tick_fetcher', 'fetch_data_task', 'manual__2024-08-24T12:21:13.878822+00:00', '--job-id', '17', '--raw', '--subdir', 'DAGS_FOLDER/data_loader.py', '--cfg-path', '/tmp/tmp60kbdd4m']
[2024-08-24T12:26:16.126+0000] {standard_task_runner.py:72} INFO - Started process 3399 to run task
[2024-08-24T12:26:16.126+0000] {standard_task_runner.py:105} INFO - Job 17: Subtask fetch_data_task
[2024-08-24T12:26:16.191+0000] {task_command.py:467} INFO - Running <TaskInstance: bybit_tick_fetcher.fetch_data_task manual__2024-08-24T12:21:13.878822+00:00 [running]> on host bf8e87922500
[2024-08-24T12:26:16.280+0000] {taskinstance.py:3122} INFO - Exporting env vars: AIRFLOW_CTX_DAG_OWNER='***' AIRFLOW_CTX_DAG_ID='bybit_tick_fetcher' AIRFLOW_CTX_TASK_ID='fetch_data_task' AIRFLOW_CTX_EXECUTION_DATE='2024-08-24T12:21:13.878822+00:00' AIRFLOW_CTX_TRY_NUMBER='2' AIRFLOW_CTX_DAG_RUN_ID='manual__2024-08-24T12:21:13.878822+00:00'
[2024-08-24T12:26:16.282+0000] {logging_mixin.py:190} INFO - Task instance is in running state
[2024-08-24T12:26:16.282+0000] {logging_mixin.py:190} INFO -  Previous state of the Task instance: queued
[2024-08-24T12:26:16.283+0000] {logging_mixin.py:190} INFO - Current task name:fetch_data_task state:running start_date:2024-08-24 12:26:16.092448+00:00
[2024-08-24T12:26:16.283+0000] {logging_mixin.py:190} INFO - Dag name:bybit_tick_fetcher and current dag run status:running
[2024-08-24T12:26:16.284+0000] {taskinstance.py:731} INFO - ::endgroup::
[2024-08-24T12:26:16.285+0000] {taskinstance.py:3301} ERROR - Task failed with exception
Traceback (most recent call last):
  File "/home/airflow/.local/lib/python3.12/site-packages/airflow/models/taskinstance.py", line 767, in _execute_task
    result = _execute_callable(context=context, **execute_callable_kwargs)
             ^^^^^^^^^^^^^^^^^^^^^^^^^^^^^^^^^^^^^^^^^^^^^^^^^^^^^^^^^^^^^
  File "/home/airflow/.local/lib/python3.12/site-packages/airflow/models/taskinstance.py", line 733, in _execute_callable
    return ExecutionCallableRunner(
           ^^^^^^^^^^^^^^^^^^^^^^^^
  File "/home/airflow/.local/lib/python3.12/site-packages/airflow/utils/operator_helpers.py", line 252, in run
    return self.func(*args, **kwargs)
           ^^^^^^^^^^^^^^^^^^^^^^^^^^
  File "/home/airflow/.local/lib/python3.12/site-packages/airflow/models/baseoperator.py", line 406, in wrapper
    return func(self, *args, **kwargs)
           ^^^^^^^^^^^^^^^^^^^^^^^^^^^
  File "/home/airflow/.local/lib/python3.12/site-packages/airflow/operators/python.py", line 238, in execute
    return_value = self.execute_callable()
                   ^^^^^^^^^^^^^^^^^^^^^^^
  File "/home/airflow/.local/lib/python3.12/site-packages/airflow/operators/python.py", line 256, in execute_callable
    return runner.run(*self.op_args, **self.op_kwargs)
           ^^^^^^^^^^^^^^^^^^^^^^^^^^^^^^^^^^^^^^^^^^^
  File "/home/airflow/.local/lib/python3.12/site-packages/airflow/utils/operator_helpers.py", line 252, in run
    return self.func(*args, **kwargs)
           ^^^^^^^^^^^^^^^^^^^^^^^^^^
  File "/opt/airflow/dags/data_loader.py", line 73, in fetch_data
    fetcher = BybitTickFetcher(logger)
              ^^^^^^^^^^^^^^^^^^^^^^^^
  File "/opt/airflow/dags/data_loader.py", line 37, in __init__
    os.makedirs(self.base_directory, exist_ok=True)
  File "<frozen os>", line 215, in makedirs
  File "<frozen os>", line 215, in makedirs
  File "<frozen os>", line 215, in makedirs
  [Previous line repeated 1 more time]
  File "<frozen os>", line 225, in makedirs
PermissionError: [Errno 13] Permission denied: '/Users'
[2024-08-24T12:26:16.306+0000] {logging_mixin.py:190} INFO - Task instance in failure state
[2024-08-24T12:26:16.321+0000] {logging_mixin.py:190} INFO - Task start:2024-08-24 12:26:16.092448+00:00 end:2024-08-24 12:26:16.300567+00:00 duration:0.208119
[2024-08-24T12:26:16.323+0000] {logging_mixin.py:190} INFO - Task:<Task(PythonOperator): fetch_data_task> dag:<DAG: bybit_tick_fetcher> dagrun:<DagRun bybit_tick_fetcher @ 2024-08-24 12:21:13.878822+00:00: manual__2024-08-24T12:21:13.878822+00:00, state:running, queued_at: 2024-08-24 12:21:13.888877+00:00. externally triggered: True>
[2024-08-24T12:26:16.324+0000] {logging_mixin.py:190} INFO - Failure caused by [Errno 13] Permission denied: '/Users'
[2024-08-24T12:26:16.325+0000] {taskinstance.py:1225} INFO - Marking task as FAILED. dag_id=bybit_tick_fetcher, task_id=fetch_data_task, run_id=manual__2024-08-24T12:21:13.878822+00:00, execution_date=20240824T122113, start_date=20240824T122616, end_date=20240824T122616
[2024-08-24T12:26:16.341+0000] {taskinstance.py:340} INFO - ::group::Post task execution logs
[2024-08-24T12:26:16.342+0000] {standard_task_runner.py:124} ERROR - Failed to execute job 17 for task fetch_data_task ([Errno 13] Permission denied: '/Users'; 3399)
Traceback (most recent call last):
  File "/home/airflow/.local/lib/python3.12/site-packages/airflow/task/task_runner/standard_task_runner.py", line 117, in _start_by_fork
    ret = args.func(args, dag=self.dag)
          ^^^^^^^^^^^^^^^^^^^^^^^^^^^^^
  File "/home/airflow/.local/lib/python3.12/site-packages/airflow/cli/cli_config.py", line 49, in command
    return func(*args, **kwargs)
           ^^^^^^^^^^^^^^^^^^^^^
  File "/home/airflow/.local/lib/python3.12/site-packages/airflow/utils/cli.py", line 115, in wrapper
    return f(*args, **kwargs)
           ^^^^^^^^^^^^^^^^^^
  File "/home/airflow/.local/lib/python3.12/site-packages/airflow/cli/commands/task_command.py", line 483, in task_run
    task_return_code = _run_task_by_selected_method(args, _dag, ti)
                       ^^^^^^^^^^^^^^^^^^^^^^^^^^^^^^^^^^^^^^^^^^^^
  File "/home/airflow/.local/lib/python3.12/site-packages/airflow/cli/commands/task_command.py", line 256, in _run_task_by_selected_method
    return _run_raw_task(args, ti)
           ^^^^^^^^^^^^^^^^^^^^^^^
  File "/home/airflow/.local/lib/python3.12/site-packages/airflow/cli/commands/task_command.py", line 341, in _run_raw_task
    return ti._run_raw_task(
           ^^^^^^^^^^^^^^^^^
  File "/home/airflow/.local/lib/python3.12/site-packages/airflow/utils/session.py", line 97, in wrapper
    return func(*args, session=session, **kwargs)
           ^^^^^^^^^^^^^^^^^^^^^^^^^^^^^^^^^^^^^^
  File "/home/airflow/.local/lib/python3.12/site-packages/airflow/models/taskinstance.py", line 2995, in _run_raw_task
    return _run_raw_task(
           ^^^^^^^^^^^^^^
  File "/home/airflow/.local/lib/python3.12/site-packages/airflow/models/taskinstance.py", line 273, in _run_raw_task
    TaskInstance._execute_task_with_callbacks(
  File "/home/airflow/.local/lib/python3.12/site-packages/airflow/models/taskinstance.py", line 3149, in _execute_task_with_callbacks
    result = self._execute_task(context, task_orig)
             ^^^^^^^^^^^^^^^^^^^^^^^^^^^^^^^^^^^^^^
  File "/home/airflow/.local/lib/python3.12/site-packages/airflow/models/taskinstance.py", line 3173, in _execute_task
    return _execute_task(self, context, task_orig)
           ^^^^^^^^^^^^^^^^^^^^^^^^^^^^^^^^^^^^^^^
  File "/home/airflow/.local/lib/python3.12/site-packages/airflow/models/taskinstance.py", line 767, in _execute_task
    result = _execute_callable(context=context, **execute_callable_kwargs)
             ^^^^^^^^^^^^^^^^^^^^^^^^^^^^^^^^^^^^^^^^^^^^^^^^^^^^^^^^^^^^^
  File "/home/airflow/.local/lib/python3.12/site-packages/airflow/models/taskinstance.py", line 733, in _execute_callable
    return ExecutionCallableRunner(
           ^^^^^^^^^^^^^^^^^^^^^^^^
  File "/home/airflow/.local/lib/python3.12/site-packages/airflow/utils/operator_helpers.py", line 252, in run
    return self.func(*args, **kwargs)
           ^^^^^^^^^^^^^^^^^^^^^^^^^^
  File "/home/airflow/.local/lib/python3.12/site-packages/airflow/models/baseoperator.py", line 406, in wrapper
    return func(self, *args, **kwargs)
           ^^^^^^^^^^^^^^^^^^^^^^^^^^^
  File "/home/airflow/.local/lib/python3.12/site-packages/airflow/operators/python.py", line 238, in execute
    return_value = self.execute_callable()
                   ^^^^^^^^^^^^^^^^^^^^^^^
  File "/home/airflow/.local/lib/python3.12/site-packages/airflow/operators/python.py", line 256, in execute_callable
    return runner.run(*self.op_args, **self.op_kwargs)
           ^^^^^^^^^^^^^^^^^^^^^^^^^^^^^^^^^^^^^^^^^^^
  File "/home/airflow/.local/lib/python3.12/site-packages/airflow/utils/operator_helpers.py", line 252, in run
    return self.func(*args, **kwargs)
           ^^^^^^^^^^^^^^^^^^^^^^^^^^
  File "/opt/airflow/dags/data_loader.py", line 73, in fetch_data
    fetcher = BybitTickFetcher(logger)
              ^^^^^^^^^^^^^^^^^^^^^^^^
  File "/opt/airflow/dags/data_loader.py", line 37, in __init__
    os.makedirs(self.base_directory, exist_ok=True)
  File "<frozen os>", line 215, in makedirs
  File "<frozen os>", line 215, in makedirs
  File "<frozen os>", line 215, in makedirs
  [Previous line repeated 1 more time]
  File "<frozen os>", line 225, in makedirs
PermissionError: [Errno 13] Permission denied: '/Users'
[2024-08-24T12:26:16.356+0000] {local_task_job_runner.py:261} INFO - Task exited with return code 1
[2024-08-24T12:26:16.372+0000] {taskinstance.py:3891} INFO - 0 downstream tasks scheduled from follow-on schedule check
[2024-08-24T12:26:16.374+0000] {local_task_job_runner.py:240} INFO - ::endgroup::
